---
title: Try... Catch... Příkaz finally - jazyka Visual Basic
description: Zjistěte, jak použít zpracování výjimek s příkazy jazyka Visual Basic Try/Catch/Finally.
ms.date: 12/07/2018
f1_keywords:
- vb.Try...Catch...Finally
- vb.when
- vb.Finally
- vb.Catch
- vb.Try
helpviewer_keywords:
- Try...Catch...Finally statements
- Try statement [Visual Basic]
- try-catch exception handling, Try...Catch...Finally statements
- error handling, while running code
- Try statement [Visual Basic], Try...Catch...Finally
- Finally keyword [Visual Basic], Try...Catch...Finally
- Catch statement [Visual Basic]
- When keyword [Visual Basic]
- Visual Basic code, handling errors while running
- structured exception handling, Try...Catch...Finally statements
ms.assetid: d6488026-ccb3-42b8-a810-0d97b9d6472b
ms.custom: seodec18
ms.openlocfilehash: 2e4fef836b08f536565105dbab76292b2fc4388e
ms.sourcegitcommit: a36cfc9dbbfc04bd88971f96e8a3f8e283c15d42
ms.translationtype: MT
ms.contentlocale: cs-CZ
ms.lasthandoff: 01/11/2019
ms.locfileid: "54221710"
---
# <a name="trycatchfinally-statement-visual-basic"></a><span data-ttu-id="20f04-103">Try...Catch....Finally – příkaz (Visual Basic)</span><span class="sxs-lookup"><span data-stu-id="20f04-103">Try...Catch...Finally Statement (Visual Basic)</span></span>

<span data-ttu-id="20f04-104">Poskytuje způsob, jak zpracovat některé nebo všechny možné chyby, které mohou nastat v daném bloku kódu, za stálého běhu programu.</span><span class="sxs-lookup"><span data-stu-id="20f04-104">Provides a way to handle some or all possible errors that may occur in a given block of code, while still running code.</span></span>

## <a name="syntax"></a><span data-ttu-id="20f04-105">Syntaxe</span><span class="sxs-lookup"><span data-stu-id="20f04-105">Syntax</span></span>

```vb
Try
    [ tryStatements ]
    [ Exit Try ]
[ Catch [ exception [ As type ] ] [ When expression ]
    [ catchStatements ]
    [ Exit Try ] ]
[ Catch ... ]
[ Finally
    [ finallyStatements ] ]
End Try
```

## <a name="parts"></a><span data-ttu-id="20f04-106">Součásti</span><span class="sxs-lookup"><span data-stu-id="20f04-106">Parts</span></span>

|<span data-ttu-id="20f04-107">Termín</span><span class="sxs-lookup"><span data-stu-id="20f04-107">Term</span></span>|<span data-ttu-id="20f04-108">Definice</span><span class="sxs-lookup"><span data-stu-id="20f04-108">Definition</span></span>|
|---|---|
|`tryStatements`|<span data-ttu-id="20f04-109">Volitelné.</span><span class="sxs-lookup"><span data-stu-id="20f04-109">Optional.</span></span> <span data-ttu-id="20f04-110">Příkazů, kde může dojít k chybě.</span><span class="sxs-lookup"><span data-stu-id="20f04-110">Statement(s) where an error can occur.</span></span> <span data-ttu-id="20f04-111">Může být složený příkaz.</span><span class="sxs-lookup"><span data-stu-id="20f04-111">Can be a compound statement.</span></span>|
|`Catch`|<span data-ttu-id="20f04-112">Volitelné.</span><span class="sxs-lookup"><span data-stu-id="20f04-112">Optional.</span></span> <span data-ttu-id="20f04-113">Více `Catch` bloky povolené.</span><span class="sxs-lookup"><span data-stu-id="20f04-113">Multiple `Catch` blocks permitted.</span></span> <span data-ttu-id="20f04-114">Pokud dojde k výjimce při zpracování `Try` blokovat, každý `Catch` je příkaz zkoumán, v textové pořadí. určíte, zda zpracovává výjimku, s `exception` reprezentující výjimku, která byla vyvolána.</span><span class="sxs-lookup"><span data-stu-id="20f04-114">If an exception occurs when processing the `Try` block, each `Catch` statement is examined in textual order to determine whether it handles the exception, with `exception` representing the exception that has been thrown.</span></span>|
|`exception`|<span data-ttu-id="20f04-115">Volitelné.</span><span class="sxs-lookup"><span data-stu-id="20f04-115">Optional.</span></span> <span data-ttu-id="20f04-116">Libovolný název proměnné.</span><span class="sxs-lookup"><span data-stu-id="20f04-116">Any variable name.</span></span> <span data-ttu-id="20f04-117">Počáteční hodnota `exception` je hodnota vyvolané chyby.</span><span class="sxs-lookup"><span data-stu-id="20f04-117">The initial value of `exception` is the value of the thrown error.</span></span> <span data-ttu-id="20f04-118">Použít s `Catch` k určení chybou byla zachycena.</span><span class="sxs-lookup"><span data-stu-id="20f04-118">Used with `Catch` to specify the error caught.</span></span> <span data-ttu-id="20f04-119">Pokud tento parametr vynechán, `Catch` příkaz zachytí jakoukoli výjimku.</span><span class="sxs-lookup"><span data-stu-id="20f04-119">If omitted, the `Catch` statement catches any exception.</span></span>|
|`type`|<span data-ttu-id="20f04-120">Volitelné.</span><span class="sxs-lookup"><span data-stu-id="20f04-120">Optional.</span></span> <span data-ttu-id="20f04-121">Určuje typ filtru třídy.</span><span class="sxs-lookup"><span data-stu-id="20f04-121">Specifies the type of class filter.</span></span> <span data-ttu-id="20f04-122">Pokud hodnota `exception` je typu určeného `type` nebo odvozeného typu, identifikátor vázán na objekt výjimky.</span><span class="sxs-lookup"><span data-stu-id="20f04-122">If the value of `exception` is of the type specified by `type` or of a derived type, the identifier becomes bound to the exception object.</span></span>|
|`When`|<span data-ttu-id="20f04-123">Volitelné.</span><span class="sxs-lookup"><span data-stu-id="20f04-123">Optional.</span></span> <span data-ttu-id="20f04-124">A `Catch` příkazem `When` klauzule zachytává výjimky pouze tehdy, když `expression` vyhodnotí jako `True`.</span><span class="sxs-lookup"><span data-stu-id="20f04-124">A `Catch` statement with a `When` clause catches exceptions only when `expression` evaluates to `True`.</span></span> <span data-ttu-id="20f04-125">A `When` až po kontrole typ výjimky, je použita klauzule a `expression` mohou odkazovat na identifikátor reprezentující výjimku.</span><span class="sxs-lookup"><span data-stu-id="20f04-125">A `When` clause is applied only after checking the type of the exception, and `expression` may refer to the identifier representing the exception.</span></span>|
|`expression`|<span data-ttu-id="20f04-126">Volitelné.</span><span class="sxs-lookup"><span data-stu-id="20f04-126">Optional.</span></span> <span data-ttu-id="20f04-127">Musí být implicitně převeditelný na `Boolean`.</span><span class="sxs-lookup"><span data-stu-id="20f04-127">Must be implicitly convertible to `Boolean`.</span></span> <span data-ttu-id="20f04-128">Libovolný výraz, který popisuje obecný filtru.</span><span class="sxs-lookup"><span data-stu-id="20f04-128">Any expression that describes a generic filter.</span></span> <span data-ttu-id="20f04-129">Obvykle se používá k filtrování podle čísla chyby.</span><span class="sxs-lookup"><span data-stu-id="20f04-129">Typically used to filter by error number.</span></span> <span data-ttu-id="20f04-130">Použít s `When` – klíčové slovo k určení podmínek, za kterých je zachycena chybu.</span><span class="sxs-lookup"><span data-stu-id="20f04-130">Used with `When` keyword to specify circumstances under which the error is caught.</span></span>|
|`catchStatements`|<span data-ttu-id="20f04-131">Volitelné.</span><span class="sxs-lookup"><span data-stu-id="20f04-131">Optional.</span></span> <span data-ttu-id="20f04-132">Příkazů pro zpracování chyb, ke kterým dochází v přidruženém `Try` bloku.</span><span class="sxs-lookup"><span data-stu-id="20f04-132">Statement(s) to handle errors that occur in the associated `Try` block.</span></span> <span data-ttu-id="20f04-133">Může být složený příkaz.</span><span class="sxs-lookup"><span data-stu-id="20f04-133">Can be a compound statement.</span></span>|
|`Exit Try`|<span data-ttu-id="20f04-134">Volitelné.</span><span class="sxs-lookup"><span data-stu-id="20f04-134">Optional.</span></span> <span data-ttu-id="20f04-135">Klíčové slovo, které se přeruší z celkového počtu `Try...Catch...Finally` struktury.</span><span class="sxs-lookup"><span data-stu-id="20f04-135">Keyword that breaks out of the `Try...Catch...Finally` structure.</span></span> <span data-ttu-id="20f04-136">Provádění pokračuje s kódem, hned za `End Try` příkazu.</span><span class="sxs-lookup"><span data-stu-id="20f04-136">Execution resumes with the code immediately following the `End Try` statement.</span></span> <span data-ttu-id="20f04-137">`Finally` Příkazu bude stále spuštěn.</span><span class="sxs-lookup"><span data-stu-id="20f04-137">The `Finally` statement will still be executed.</span></span> <span data-ttu-id="20f04-138">Není povoleno v `Finally` bloky.</span><span class="sxs-lookup"><span data-stu-id="20f04-138">Not allowed in `Finally` blocks.</span></span>|
|`Finally`|<span data-ttu-id="20f04-139">Volitelné.</span><span class="sxs-lookup"><span data-stu-id="20f04-139">Optional.</span></span> <span data-ttu-id="20f04-140">A `Finally` bloku je vždy spuštěn při provádění opustí libovolné části `Try...Catch` příkazu.</span><span class="sxs-lookup"><span data-stu-id="20f04-140">A `Finally` block is always executed when execution leaves any part of the `Try...Catch` statement.</span></span>|
|`finallyStatements`|<span data-ttu-id="20f04-141">Volitelné.</span><span class="sxs-lookup"><span data-stu-id="20f04-141">Optional.</span></span> <span data-ttu-id="20f04-142">Příkazů, který se spustí po další zpracování chyby došlo k chybě.</span><span class="sxs-lookup"><span data-stu-id="20f04-142">Statement(s) that are executed after all other error processing has occurred.</span></span>|
|`End Try`|<span data-ttu-id="20f04-143">Ukončuje `Try...Catch...Finally` struktury.</span><span class="sxs-lookup"><span data-stu-id="20f04-143">Terminates the `Try...Catch...Finally` structure.</span></span>|

## <a name="remarks"></a><span data-ttu-id="20f04-144">Poznámky</span><span class="sxs-lookup"><span data-stu-id="20f04-144">Remarks</span></span>

<span data-ttu-id="20f04-145">Pokud očekáváte, že konkrétní výjimka muže vzniknout během určité části kódu, vložte kód `Try` blokovat a použít `Catch` blok se zachovat kontrolu a zpracovala výjimku. Pokud k němu dojde.</span><span class="sxs-lookup"><span data-stu-id="20f04-145">If you expect that a particular exception might occur during a particular section of code, put the code in a `Try` block and use a `Catch` block to retain control and handle the exception if it occurs.</span></span>

<span data-ttu-id="20f04-146">A `Try…Catch` příkaz se skládá z `Try` bloku, za nímž následuje jedna nebo více `Catch` klauzule, které určují obslužné rutiny pro různé výjimky.</span><span class="sxs-lookup"><span data-stu-id="20f04-146">A `Try…Catch` statement consists of a `Try` block followed by one or more `Catch` clauses, which specify handlers for various exceptions.</span></span> <span data-ttu-id="20f04-147">Když je výjimka vyvolána `Try` blokovat, Visual Basic vyhledá `Catch` příkaz, který zpracovává výjimku.</span><span class="sxs-lookup"><span data-stu-id="20f04-147">When an exception is thrown in a `Try` block, Visual Basic looks for the `Catch` statement that handles the exception.</span></span> <span data-ttu-id="20f04-148">Pokud odpovídající `Catch` příkaz nebyl nalezen, Visual Basic zjišťuje metody, která volá metodu aktuální výše v zásobníku volání a tak dále.</span><span class="sxs-lookup"><span data-stu-id="20f04-148">If a matching `Catch` statement is not found, Visual Basic examines the method that called the current method, and so on up the call stack.</span></span> <span data-ttu-id="20f04-149">Pokud ne `Catch` nalezen blok, Visual Basic zobrazí zprávu neošetřená výjimka na uživatele a zastaví provádění programu.</span><span class="sxs-lookup"><span data-stu-id="20f04-149">If no `Catch` block is found, Visual Basic displays an unhandled exception message to the user and stops execution of the program.</span></span>

<span data-ttu-id="20f04-150">Můžete použít více než jednu `Catch` výroky `Try…Catch` příkazu.</span><span class="sxs-lookup"><span data-stu-id="20f04-150">You can use more than one `Catch` statement in a `Try…Catch` statement.</span></span> <span data-ttu-id="20f04-151">Pokud to provedete, pořadí `Catch` klauzulí je důležité, protože jsou zkoumány podle pořadí.</span><span class="sxs-lookup"><span data-stu-id="20f04-151">If you do this, the order of the `Catch` clauses is significant because they are examined in order.</span></span> <span data-ttu-id="20f04-152">Zachycení více specifické výjimky než těch, které jsou specifické pro less.</span><span class="sxs-lookup"><span data-stu-id="20f04-152">Catch the more specific exceptions before the less specific ones.</span></span>

<span data-ttu-id="20f04-153">Následující `Catch` příkaz podmínky jsou po nejméně konkrétní a zachytí všechny výjimky, které jsou odvozeny z <xref:System.Exception> třídy.</span><span class="sxs-lookup"><span data-stu-id="20f04-153">The following `Catch` statement conditions are the least specific, and will catch all exceptions that derive from the <xref:System.Exception> class.</span></span> <span data-ttu-id="20f04-154">Jednu z těchto variant má obvykle použít jako poslední `Catch` blokovat `Try...Catch...Finally` struktury po zachycení specifické výjimky očekáváte.</span><span class="sxs-lookup"><span data-stu-id="20f04-154">You should ordinarily use one of these variations as the last `Catch` block in the `Try...Catch...Finally` structure, after catching all the specific exceptions you expect.</span></span> <span data-ttu-id="20f04-155">Tok řízení můžete nikdy nedorazí `Catch` blok, který následuje některý z těchto variant.</span><span class="sxs-lookup"><span data-stu-id="20f04-155">Control flow can never reach a `Catch` block that follows either of these variations.</span></span>

- <span data-ttu-id="20f04-156">`type` Je `Exception`, například: `Catch ex As Exception`</span><span class="sxs-lookup"><span data-stu-id="20f04-156">The `type` is `Exception`, for example: `Catch ex As Exception`</span></span>

- <span data-ttu-id="20f04-157">Příkaz nemá žádné `exception` proměnných, například: `Catch`</span><span class="sxs-lookup"><span data-stu-id="20f04-157">The statement has no `exception` variable, for example: `Catch`</span></span>

<span data-ttu-id="20f04-158">Když `Try…Catch…Finally` příkaz je vnořená v jiném `Try` bloku, Visual Basic nejprve zkontroluje každý `Catch` příkaz v nejvnitřnější `Try` bloku.</span><span class="sxs-lookup"><span data-stu-id="20f04-158">When a `Try…Catch…Finally` statement is nested in another `Try` block, Visual Basic first examines each `Catch` statement in the innermost `Try` block.</span></span> <span data-ttu-id="20f04-159">Pokud neexistuje odpovídající `Catch` příkaz nenajde, vyhledávání pokračuje do `Catch` ve vnějším `Try…Catch…Finally` bloku.</span><span class="sxs-lookup"><span data-stu-id="20f04-159">If no matching `Catch` statement is found, the search proceeds to the `Catch` statements of the outer `Try…Catch…Finally` block.</span></span>

<span data-ttu-id="20f04-160">Lokální proměnné z `Try` nejsou k dispozici v bloku `Catch` blokovat, protože jde o samostatné bloky.</span><span class="sxs-lookup"><span data-stu-id="20f04-160">Local variables from a `Try` block are not available in a `Catch` block because they are separate blocks.</span></span> <span data-ttu-id="20f04-161">Pokud chcete použít proměnnou ve více než jeden blok, deklarace proměnné mimo `Try...Catch...Finally` struktury.</span><span class="sxs-lookup"><span data-stu-id="20f04-161">If you want to use a variable in more than one block, declare the variable outside the `Try...Catch...Finally` structure.</span></span>

> [!TIP]
> <span data-ttu-id="20f04-162">`Try…Catch…Finally` Příkaz je dostupný jako fragment kódu technologie IntelliSense.</span><span class="sxs-lookup"><span data-stu-id="20f04-162">The `Try…Catch…Finally` statement is available as an IntelliSense code snippet.</span></span> <span data-ttu-id="20f04-163">Ve Správci fragmentů kódu, rozbalte **vzorky kódu – If, For Each, Try Catch, vlastnost atd**a potom **zpracování chyb (výjimek)**.</span><span class="sxs-lookup"><span data-stu-id="20f04-163">In the Code Snippets Manager, expand **Code Patterns - If, For Each, Try Catch, Property, etc**, and then **Error Handling (Exceptions)**.</span></span> <span data-ttu-id="20f04-164">Další informace najdete v tématu [fragmenty kódu](/visualstudio/ide/code-snippets).</span><span class="sxs-lookup"><span data-stu-id="20f04-164">For more information, see [Code Snippets](/visualstudio/ide/code-snippets).</span></span>

## <a name="finally-block"></a><span data-ttu-id="20f04-165">Blok finally</span><span class="sxs-lookup"><span data-stu-id="20f04-165">Finally block</span></span>

<span data-ttu-id="20f04-166">Pokud máte jeden nebo více příkazů, které musí spustit před ukončením `Try` strukturu, použijte `Finally` bloku.</span><span class="sxs-lookup"><span data-stu-id="20f04-166">If you have one or more statements that must run before you exit the `Try` structure, use a `Finally` block.</span></span> <span data-ttu-id="20f04-167">Řízení se předá `Finally` blokovat těsně před plánovaným začátkem předá z celkového počtu `Try…Catch` struktury.</span><span class="sxs-lookup"><span data-stu-id="20f04-167">Control passes to the `Finally` block just before it passes out of the `Try…Catch` structure.</span></span> <span data-ttu-id="20f04-168">To platí i v případě, že dojde k výjimce kdekoli uvnitř `Try` struktury.</span><span class="sxs-lookup"><span data-stu-id="20f04-168">This is true even if an exception occurs anywhere inside the `Try` structure.</span></span>

<span data-ttu-id="20f04-169">A `Finally` bloku je užitečné pro spuštění jakéhokoli kódu, které musí spustit i v případě, že dojde k výjimce.</span><span class="sxs-lookup"><span data-stu-id="20f04-169">A `Finally` block is useful for running any code that must execute even if there is an exception.</span></span> <span data-ttu-id="20f04-170">Řízení je předáno `Finally` blokovat bez ohledu na to, jak `Try...Catch` blokovat ukončí.</span><span class="sxs-lookup"><span data-stu-id="20f04-170">Control is passed to the `Finally` block regardless of how the `Try...Catch` block exits.</span></span>

<span data-ttu-id="20f04-171">Kód v `Finally` blok i v případě, že váš kód zjistí `Return` příkaz v `Try` nebo `Catch` bloku.</span><span class="sxs-lookup"><span data-stu-id="20f04-171">The code in a `Finally` block runs even if your code encounters a `Return` statement in a `Try` or `Catch` block.</span></span> <span data-ttu-id="20f04-172">Ovládací prvek z nepředává `Try` nebo `Catch` blokovat na odpovídající `Finally` blokovat v následujících případech:</span><span class="sxs-lookup"><span data-stu-id="20f04-172">Control does not pass from a `Try` or `Catch` block to the corresponding `Finally` block in the following cases:</span></span>

- <span data-ttu-id="20f04-173">[End – příkaz](end-statement.md) dochází v `Try` nebo `Catch` bloku.</span><span class="sxs-lookup"><span data-stu-id="20f04-173">An [End Statement](end-statement.md) is encountered in the `Try` or `Catch` block.</span></span>

- <span data-ttu-id="20f04-174">A <xref:System.StackOverflowException> je vyvolána `Try` nebo `Catch` bloku.</span><span class="sxs-lookup"><span data-stu-id="20f04-174">A <xref:System.StackOverflowException> is thrown in the `Try` or `Catch` block.</span></span>

<span data-ttu-id="20f04-175">Není platné. explicitně přenést do spuštění `Finally` bloku.</span><span class="sxs-lookup"><span data-stu-id="20f04-175">It is not valid to explicitly transfer execution into a `Finally` block.</span></span> <span data-ttu-id="20f04-176">Přenos z celkového počtu spuštění `Finally` blok není platný, s výjimkou prostřednictvím výjimku.</span><span class="sxs-lookup"><span data-stu-id="20f04-176">Transferring execution out of a `Finally` block is not valid, except through an exception.</span></span>

<span data-ttu-id="20f04-177">Pokud `Try` alespoň jeden příkaz neobsahuje `Catch` bloku, musí obsahovat `Finally` bloku.</span><span class="sxs-lookup"><span data-stu-id="20f04-177">If a `Try` statement does not contain at least one `Catch` block, it must contain a `Finally` block.</span></span>

> [!TIP]
> <span data-ttu-id="20f04-178">Pokud nemáte zachytit specifické výjimky `Using` se chová stejně jako `Try…Finally` bloku a záruky zacházení s prostředky, bez ohledu na to, jak ukončení bloku.</span><span class="sxs-lookup"><span data-stu-id="20f04-178">If you do not have to catch specific exceptions, the `Using` statement behaves like a `Try…Finally` block, and guarantees disposal of the resources, regardless of how you exit the block.</span></span> <span data-ttu-id="20f04-179">To platí dokonce i s neošetřenou výjimkou.</span><span class="sxs-lookup"><span data-stu-id="20f04-179">This is true even with an unhandled exception.</span></span> <span data-ttu-id="20f04-180">Další informace najdete v tématu [příkazu Using](using-statement.md).</span><span class="sxs-lookup"><span data-stu-id="20f04-180">For more information, see [Using Statement](using-statement.md).</span></span>

## <a name="exception-argument"></a><span data-ttu-id="20f04-181">Výjimky argumentu</span><span class="sxs-lookup"><span data-stu-id="20f04-181">Exception argument</span></span>

<span data-ttu-id="20f04-182">`Catch` Bloku `exception` je argument instancí <xref:System.Exception> třídu nebo třídu odvozenou od `Exception` třídy.</span><span class="sxs-lookup"><span data-stu-id="20f04-182">The `Catch` block `exception` argument is an instance of the <xref:System.Exception> class or a class that derives from the `Exception` class.</span></span> <span data-ttu-id="20f04-183">`Exception` Odpovídá chyby, ke které došlo k chybě v instanci třídy `Try` bloku.</span><span class="sxs-lookup"><span data-stu-id="20f04-183">The `Exception` class instance corresponds to the error that occurred in the `Try` block.</span></span>

<span data-ttu-id="20f04-184">Vlastnosti `Exception` objektu zobrazíte nápovědu, jak určit příčinu a umístění výjimky.</span><span class="sxs-lookup"><span data-stu-id="20f04-184">The properties of the `Exception` object help to identify the cause and location of an exception.</span></span> <span data-ttu-id="20f04-185">Například <xref:System.Exception.StackTrace%2A> seznamů vlastností volané metody, která vedla k výjimce, pomáhá najít, kde došlo k chybě v kódu.</span><span class="sxs-lookup"><span data-stu-id="20f04-185">For example, the <xref:System.Exception.StackTrace%2A> property lists the called methods that led to the exception, helping you find where the error occurred in the code.</span></span> <span data-ttu-id="20f04-186"><xref:System.Exception.Message%2A> vrátí zprávu, která popisuje výjimku.</span><span class="sxs-lookup"><span data-stu-id="20f04-186"><xref:System.Exception.Message%2A> returns a message that describes the exception.</span></span> <span data-ttu-id="20f04-187"><xref:System.Exception.HelpLink%2A> Vrátí odkaz na související soubor nápovědy.</span><span class="sxs-lookup"><span data-stu-id="20f04-187"><xref:System.Exception.HelpLink%2A> returns a link to an associated Help file.</span></span> <span data-ttu-id="20f04-188"><xref:System.Exception.InnerException%2A> Vrátí `Exception` objektu, která způsobila aktuální výjimku nebo vrátí `Nothing` Pokud neexistuje žádná původní `Exception`.</span><span class="sxs-lookup"><span data-stu-id="20f04-188"><xref:System.Exception.InnerException%2A> returns the `Exception` object that caused the current exception, or it returns `Nothing` if there is no original `Exception`.</span></span>

## <a name="considerations-when-using-a-trycatch-statement"></a><span data-ttu-id="20f04-189">Informace týkající se použití Try... Catch – příkaz</span><span class="sxs-lookup"><span data-stu-id="20f04-189">Considerations when using a Try…Catch statement</span></span>

<span data-ttu-id="20f04-190">Použití `Try…Catch` příkaz pouze k signalizaci výskytu neobvyklých nebo neočekávané události.</span><span class="sxs-lookup"><span data-stu-id="20f04-190">Use a `Try…Catch` statement only to signal the occurrence of unusual or unanticipated program events.</span></span> <span data-ttu-id="20f04-191">Důvody patří:</span><span class="sxs-lookup"><span data-stu-id="20f04-191">Reasons for this include the following:</span></span>

- <span data-ttu-id="20f04-192">Zachycování výjimek za běhu vytvoří další režii a by mohla být pomalejší než předběžné kontroly, aby výjimky.</span><span class="sxs-lookup"><span data-stu-id="20f04-192">Catching exceptions at runtime creates additional overhead, and is likely to be slower than pre-checking to avoid exceptions.</span></span>

- <span data-ttu-id="20f04-193">Pokud `Catch` bloku nezpracovává správně, výjimka nemusí být uveden správně pro uživatele.</span><span class="sxs-lookup"><span data-stu-id="20f04-193">If a `Catch` block is not handled correctly, the exception might not be reported correctly to users.</span></span>

- <span data-ttu-id="20f04-194">Zpracování výjimek je program složitější.</span><span class="sxs-lookup"><span data-stu-id="20f04-194">Exception handling makes a program more complex.</span></span>

<span data-ttu-id="20f04-195">Není vždy nutné `Try…Catch` příkaz podmínku, která by mohla nastat.</span><span class="sxs-lookup"><span data-stu-id="20f04-195">You do not always need a `Try…Catch` statement to check for a condition that is likely to occur.</span></span> <span data-ttu-id="20f04-196">Následující příklad zkontroluje, zda soubor existuje. před pokusem o otevření.</span><span class="sxs-lookup"><span data-stu-id="20f04-196">The following example checks whether a file exists before trying to open it.</span></span> <span data-ttu-id="20f04-197">To snižuje nutnost zachycení výjimky vyvolané <xref:System.IO.File.OpenText%2A> metody.</span><span class="sxs-lookup"><span data-stu-id="20f04-197">This reduces the need for catching an exception thrown by the <xref:System.IO.File.OpenText%2A> method.</span></span>

[!code-vb[VbVbalrStatements#94](~/samples/snippets/visualbasic/VS_Snippets_VBCSharp/VbVbalrStatements/VB/Class1.vb#94)]

<span data-ttu-id="20f04-198">Ujistěte se, že kód v `Catch` bloky může hlásit výjimky na uživatele, správně prostřednictvím bezpečné pro vlákna protokolování nebo příslušné zprávy.</span><span class="sxs-lookup"><span data-stu-id="20f04-198">Ensure that code in `Catch` blocks can properly report exceptions to users, whether through thread-safe logging or appropriate messages.</span></span> <span data-ttu-id="20f04-199">V opačném případě může zůstat výjimky neznámý.</span><span class="sxs-lookup"><span data-stu-id="20f04-199">Otherwise, exceptions might remain unknown.</span></span>

## <a name="async-methods"></a><span data-ttu-id="20f04-200">Asynchronní metody</span><span class="sxs-lookup"><span data-stu-id="20f04-200">Async methods</span></span>

<span data-ttu-id="20f04-201">Pokud určíte metodu s [asynchronní](../modifiers/async.md) modifikátor, můžete použít [Await](../operators/await-operator.md) operátor v metodě.</span><span class="sxs-lookup"><span data-stu-id="20f04-201">If you mark a method with the [Async](../modifiers/async.md) modifier, you can use the [Await](../operators/await-operator.md) operator in the method.</span></span> <span data-ttu-id="20f04-202">Příkaz s `Await` operátor pozastaví provádění metody až do dokončení očekávané úlohy.</span><span class="sxs-lookup"><span data-stu-id="20f04-202">A statement with the `Await` operator suspends execution of the method until the awaited task completes.</span></span> <span data-ttu-id="20f04-203">Úloha představuje probíhající práci.</span><span class="sxs-lookup"><span data-stu-id="20f04-203">The task represents ongoing work.</span></span> <span data-ttu-id="20f04-204">Když úloha, která je přidružena `Await` operátor dokončí, obnoví spuštění ve stejnou metodu.</span><span class="sxs-lookup"><span data-stu-id="20f04-204">When the task that's associated with the `Await` operator finishes, execution resumes in the same method.</span></span> <span data-ttu-id="20f04-205">Další informace najdete v tématu [tok řízení v asynchronních programech](../../../visual-basic/programming-guide/concepts/async/control-flow-in-async-programs.md).</span><span class="sxs-lookup"><span data-stu-id="20f04-205">For more information, see [Control Flow in Async Programs](../../../visual-basic/programming-guide/concepts/async/control-flow-in-async-programs.md).</span></span>

<span data-ttu-id="20f04-206">Úkol vrácený asynchronní metody ukončit v chybovém stavu, která je dokončena z důvodu neošetřené výjimky.</span><span class="sxs-lookup"><span data-stu-id="20f04-206">A task returned by an Async method may end in a faulted state, indicating that it completed due to an unhandled exception.</span></span> <span data-ttu-id="20f04-207">Úkol může také skončit ve zrušeném stavu, což vede `OperationCanceledException` vyvolané z výrazu await.</span><span class="sxs-lookup"><span data-stu-id="20f04-207">A task may also end in a canceled state, which results in an `OperationCanceledException` being thrown out of the await expression.</span></span> <span data-ttu-id="20f04-208">K zachycení buď typ výjimky, umístěte `Await` výraz, který je spojen s úlohou v `Try` blokovat a zachytit výjimku v `Catch` bloku.</span><span class="sxs-lookup"><span data-stu-id="20f04-208">To catch either type of exception, place the `Await` expression that's associated with the task in a `Try` block, and catch the exception in the `Catch` block.</span></span> <span data-ttu-id="20f04-209">Příklad je k dispozici dále v tomto tématu.</span><span class="sxs-lookup"><span data-stu-id="20f04-209">An example is provided later in this topic.</span></span>

<span data-ttu-id="20f04-210">Úloha může být v chybovém stavu, protože více výjimek tým byl zodpovědný za jeho přerušením.</span><span class="sxs-lookup"><span data-stu-id="20f04-210">A task can be in a faulted state because multiple exceptions were responsible for its faulting.</span></span> <span data-ttu-id="20f04-211">Úloha může být například výsledek volání <xref:System.Threading.Tasks.Task.WhenAll%2A?displayProperty=nameWithType>.</span><span class="sxs-lookup"><span data-stu-id="20f04-211">For example, the task might be the result of a call to <xref:System.Threading.Tasks.Task.WhenAll%2A?displayProperty=nameWithType>.</span></span> <span data-ttu-id="20f04-212">Když budete očekávat takový úkol, zachycené výjimky je pouze jednu z výjimek a nelze předpovědět, které k výjimce.</span><span class="sxs-lookup"><span data-stu-id="20f04-212">When you await such a task, the caught exception is only one of the exceptions, and you can't predict which exception will be caught.</span></span> <span data-ttu-id="20f04-213">Příklad je k dispozici dále v tomto tématu.</span><span class="sxs-lookup"><span data-stu-id="20f04-213">An example is provided later in this topic.</span></span>

<span data-ttu-id="20f04-214">`Await` Výraz nemůže být uvnitř `Catch` bloku nebo `Finally` bloku.</span><span class="sxs-lookup"><span data-stu-id="20f04-214">An `Await` expression can't be inside a `Catch` block or `Finally` block.</span></span>

## <a name="iterators"></a><span data-ttu-id="20f04-215">Iterátory</span><span class="sxs-lookup"><span data-stu-id="20f04-215">Iterators</span></span>

<span data-ttu-id="20f04-216">Funkce iterátoru nebo `Get` přistupující objekt provádí vlastní iterace nad kolekcí.</span><span class="sxs-lookup"><span data-stu-id="20f04-216">An iterator function or `Get` accessor performs a custom iteration over a collection.</span></span> <span data-ttu-id="20f04-217">Iterátor používá [Yield](yield-statement.md) příkaz k vrácení každého prvku kolekce jeden po druhém.</span><span class="sxs-lookup"><span data-stu-id="20f04-217">An iterator uses a [Yield](yield-statement.md) statement to return each element of the collection one at a time.</span></span> <span data-ttu-id="20f04-218">Volání funkce iterátoru pomocí [For Each... Další příkaz](for-each-next-statement.md).</span><span class="sxs-lookup"><span data-stu-id="20f04-218">You call an iterator function by using a [For Each...Next Statement](for-each-next-statement.md).</span></span>

<span data-ttu-id="20f04-219">A `Yield` příkaz může být v rámci `Try` bloku.</span><span class="sxs-lookup"><span data-stu-id="20f04-219">A `Yield` statement can be inside a `Try` block.</span></span> <span data-ttu-id="20f04-220">A `Try` blok, který obsahuje `Yield` může mít příkaz `Catch` a ostatní porty blokuje může mít `Finally` bloku.</span><span class="sxs-lookup"><span data-stu-id="20f04-220">A `Try` block that contains a `Yield` statement can have `Catch` blocks, and can have a `Finally` block.</span></span> <span data-ttu-id="20f04-221">Najdete v části "zkuste bloky v jazyce Visual Basic" [iterátory](../../programming-guide/concepts/iterators.md) příklad.</span><span class="sxs-lookup"><span data-stu-id="20f04-221">See the "Try Blocks in Visual Basic" section of [Iterators](../../programming-guide/concepts/iterators.md) for an example.</span></span>

<span data-ttu-id="20f04-222">A `Yield` příkaz nejde provést uvnitř `Catch` bloku nebo `Finally` bloku.</span><span class="sxs-lookup"><span data-stu-id="20f04-222">A `Yield` statement cannot be inside a `Catch` block or a `Finally` block.</span></span>

<span data-ttu-id="20f04-223">Pokud `For Each` text (mimo funkce iterátoru) vyvolá výjimku, `Catch` bloku funkce iterátoru není spuštěn, ale `Finally` je proveden blok v funkce iterátoru.</span><span class="sxs-lookup"><span data-stu-id="20f04-223">If the `For Each` body (outside of the iterator function) throws an exception, a `Catch` block in the iterator function is not executed, but a `Finally` block in the iterator function is executed.</span></span> <span data-ttu-id="20f04-224">A `Catch` bloku funkce iterátoru zachytává pouze výjimky, ke kterým dochází uvnitř funkce iterátoru.</span><span class="sxs-lookup"><span data-stu-id="20f04-224">A `Catch` block inside an iterator function catches only exceptions that occur inside the iterator function.</span></span>

## <a name="partial-trust-situations"></a><span data-ttu-id="20f04-225">Situacích částečné důvěryhodnosti</span><span class="sxs-lookup"><span data-stu-id="20f04-225">Partial-trust situations</span></span>

<span data-ttu-id="20f04-226">V situacích částečné důvěryhodnosti, jako je například aplikace hostované ve sdílené síťové složce `Try...Catch...Finally` nezachytí výjimky zabezpečení, ke kterým dochází před vyvoláním metody, která obsahuje volání.</span><span class="sxs-lookup"><span data-stu-id="20f04-226">In partial-trust situations, such as an application hosted on a network share, `Try...Catch...Finally` does not catch security exceptions that occur before the method that contains the call is invoked.</span></span> <span data-ttu-id="20f04-227">Následující příklad, když vložit ho do sdílené složky serveru a spusťte z něj, vytvoří chybu "System.Security.SecurityException: Požadavek se nezdařil."</span><span class="sxs-lookup"><span data-stu-id="20f04-227">The following example, when you put it on a server share and run from there, produces the error "System.Security.SecurityException: Request Failed."</span></span> <span data-ttu-id="20f04-228">Další informace o bezpečnostním výjimkám, najdete v článku <xref:System.Security.SecurityException> třídy.</span><span class="sxs-lookup"><span data-stu-id="20f04-228">For more information about security exceptions, see the <xref:System.Security.SecurityException> class.</span></span>

[!code-vb[VbVbalrStatements#85](~/samples/snippets/visualbasic/VS_Snippets_VBCSharp/VbVbalrStatements/VB/Class1.vb#85)]

<span data-ttu-id="20f04-229">V takové částečným vztahem důvěryhodnosti situace, je nutné umístit `Process.Start` příkaz v samostatném `Sub`.</span><span class="sxs-lookup"><span data-stu-id="20f04-229">In such a partial-trust situation, you have to put the `Process.Start` statement in a separate `Sub`.</span></span> <span data-ttu-id="20f04-230">Počáteční volání `Sub` se nezdaří.</span><span class="sxs-lookup"><span data-stu-id="20f04-230">The initial call to the `Sub` will fail.</span></span> <span data-ttu-id="20f04-231">Díky tomu `Try...Catch` má zachytit před `Sub` obsahující `Process.Start` je spuštěná a vytváří výjimku zabezpečení.</span><span class="sxs-lookup"><span data-stu-id="20f04-231">This enables `Try...Catch` to catch it before the `Sub` that contains `Process.Start` is started and the security exception produced.</span></span>

## <a name="examples"></a><span data-ttu-id="20f04-232">Příklady</span><span class="sxs-lookup"><span data-stu-id="20f04-232">Examples</span></span>

### <a name="the-structure-of-trycatchfinally"></a><span data-ttu-id="20f04-233">Struktury Try... Catch... Nakonec</span><span class="sxs-lookup"><span data-stu-id="20f04-233">The structure of Try...Catch...Finally</span></span>

<span data-ttu-id="20f04-234">Následující příklad ukazuje strukturu `Try...Catch...Finally` příkazu.</span><span class="sxs-lookup"><span data-stu-id="20f04-234">The following example illustrates the structure of the `Try...Catch...Finally` statement.</span></span>

[!code-vb[VbVbalrStatements#86](~/samples/snippets/visualbasic/VS_Snippets_VBCSharp/VbVbalrStatements/VB/Class1.vb#86)]  

### <a name="exception-in-a-method-called-from-a-try-block"></a><span data-ttu-id="20f04-235">Výjimka v metodě volat z bloku Try</span><span class="sxs-lookup"><span data-stu-id="20f04-235">Exception in a method called from a Try block</span></span>

<span data-ttu-id="20f04-236">V následujícím příkladu `CreateException` vyvolá metoda výjimku `NullReferenceException`.</span><span class="sxs-lookup"><span data-stu-id="20f04-236">In the following example, the `CreateException` method throws a `NullReferenceException`.</span></span> <span data-ttu-id="20f04-237">Není v kódu, který generuje výjimku `Try` bloku.</span><span class="sxs-lookup"><span data-stu-id="20f04-237">The code that generates the exception is not in a `Try` block.</span></span> <span data-ttu-id="20f04-238">Proto `CreateException` metodu ke zpracování výjimky.</span><span class="sxs-lookup"><span data-stu-id="20f04-238">Therefore, the `CreateException` method does not handle the exception.</span></span> <span data-ttu-id="20f04-239">`RunSample` Metoda zpracování výjimky, protože volání `CreateException` metoda je `Try` bloku.</span><span class="sxs-lookup"><span data-stu-id="20f04-239">The `RunSample` method does handle the exception because the call to the `CreateException` method is in a `Try` block.</span></span>

<span data-ttu-id="20f04-240">Příklad obsahuje `Catch` příkazy pro několik typů výjimek, seřazené od nejkonkrétnější většinu obecných.</span><span class="sxs-lookup"><span data-stu-id="20f04-240">The example includes `Catch` statements for several types of exceptions, ordered from the most specific to the most general.</span></span>

[!code-vb[VbVbalrStatements#91](~/samples/snippets/visualbasic/VS_Snippets_VBCSharp/VbVbalrStatements/VB/Class1.vb#91)]

### <a name="the-catch-when-statement"></a><span data-ttu-id="20f04-241">Příkaz Catch, když</span><span class="sxs-lookup"><span data-stu-id="20f04-241">The Catch When statement</span></span>

<span data-ttu-id="20f04-242">Následující příklad ukazuje způsob použití `Catch When` příkaz k filtrování podmíněný výraz.</span><span class="sxs-lookup"><span data-stu-id="20f04-242">The following example shows how to use a `Catch When` statement to filter on a conditional expression.</span></span> <span data-ttu-id="20f04-243">Pokud podmíněný výraz je vyhodnocen jako `True`, kód `Catch` blok.</span><span class="sxs-lookup"><span data-stu-id="20f04-243">If the conditional expression evaluates to `True`, the code in the `Catch` block runs.</span></span>

[!code-vb[VbVbalrStatements#92](~/samples/snippets/visualbasic/VS_Snippets_VBCSharp/VbVbalrStatements/VB/Class1.vb#92)]

### <a name="nested-try-statements"></a><span data-ttu-id="20f04-244">Vnořené příkazy Try</span><span class="sxs-lookup"><span data-stu-id="20f04-244">Nested Try statements</span></span>

<span data-ttu-id="20f04-245">Následující příklad obsahuje `Try…Catch` příkaz, který je součástí `Try` bloku.</span><span class="sxs-lookup"><span data-stu-id="20f04-245">The following example has a `Try…Catch` statement that is contained in a `Try` block.</span></span> <span data-ttu-id="20f04-246">Vnitřní `Catch` bloku vyvolá výjimku, která má jeho `InnerException` nastavenou na původní výjimku.</span><span class="sxs-lookup"><span data-stu-id="20f04-246">The inner `Catch` block throws an exception that has its `InnerException` property set to the original exception.</span></span> <span data-ttu-id="20f04-247">Vnější `Catch` bloku hlásí svůj vlastní výjimku a vnitřní výjimku.</span><span class="sxs-lookup"><span data-stu-id="20f04-247">The outer `Catch` block reports its own exception and the inner exception.</span></span>

[!code-vb[VbVbalrStatements#93](~/samples/snippets/visualbasic/VS_Snippets_VBCSharp/VbVbalrStatements/VB/Class1.vb#93)]

### <a name="exception-handling-for-async-methods"></a><span data-ttu-id="20f04-248">Zpracování výjimek pro asynchronní metody</span><span class="sxs-lookup"><span data-stu-id="20f04-248">Exception handling for async methods</span></span>

<span data-ttu-id="20f04-249">Následující příklad ukazuje zpracování výjimek pro asynchronní metody.</span><span class="sxs-lookup"><span data-stu-id="20f04-249">The following example illustrates exception handling for async methods.</span></span> <span data-ttu-id="20f04-250">Zachytit výjimku, která se vztahuje na asynchronní úlohy, `Await` výraz `Try` bloku volajícího a výjimky je zachycena v `Catch` bloku.</span><span class="sxs-lookup"><span data-stu-id="20f04-250">To catch an exception that applies to an async task, the `Await` expression is in a `Try` block of the caller, and the exception is caught in the `Catch` block.</span></span>

<span data-ttu-id="20f04-251">Zrušením komentáře u `Throw New Exception` řádek v příkladu předvést zpracování výjimek.</span><span class="sxs-lookup"><span data-stu-id="20f04-251">Uncomment the `Throw New Exception` line in the example to demonstrate exception handling.</span></span> <span data-ttu-id="20f04-252">Výjimka je zachycena v `Catch` blokovat, úkolu `IsFaulted` je nastavena na `True`a úkolu `Exception.InnerException` je nastavena na výjimku.</span><span class="sxs-lookup"><span data-stu-id="20f04-252">The exception is caught in the `Catch` block, the task's `IsFaulted` property is set to `True`, and the task's `Exception.InnerException` property is set to the exception.</span></span>

<span data-ttu-id="20f04-253">Zrušením komentáře u `Throw New OperationCancelledException` řádku předvést, co se stane, když zrušíte asynchronní proces.</span><span class="sxs-lookup"><span data-stu-id="20f04-253">Uncomment the `Throw New OperationCancelledException` line to demonstrate what happens when you cancel an asynchronous process.</span></span> <span data-ttu-id="20f04-254">Výjimka je zachycena v `Catch` bloku a tato úloha `IsCanceled` je nastavena na `True`.</span><span class="sxs-lookup"><span data-stu-id="20f04-254">The exception is caught in the `Catch` block, and the task's `IsCanceled` property is set to `True`.</span></span> <span data-ttu-id="20f04-255">Ale za určitých podmínek, které se nevztahují na tomto příkladu `IsFaulted` je nastavena na `True` a `IsCanceled` je nastavena na `False`.</span><span class="sxs-lookup"><span data-stu-id="20f04-255">However, under some conditions that don't apply to this example, `IsFaulted` is set to `True` and `IsCanceled` is set to `False`.</span></span>

[!code-vb[csAsyncExceptions#1](~/samples/snippets/visualbasic/VS_Snippets_VBCSharp/csasyncexceptions/vb/class1.vb#1)]

### <a name="handling-multiple-exceptions-in-async-methods"></a><span data-ttu-id="20f04-256">Zpracování více výjimky v asynchronních metodách</span><span class="sxs-lookup"><span data-stu-id="20f04-256">Handling multiple exceptions in async methods</span></span>

<span data-ttu-id="20f04-257">Následující příklad ukazuje zpracování výjimek, kde více úkolů může vést k více výjimek.</span><span class="sxs-lookup"><span data-stu-id="20f04-257">The following example illustrates exception handling where multiple tasks can result in multiple exceptions.</span></span> <span data-ttu-id="20f04-258">`Try` Má bloku `Await` výraz pro úlohu, která <xref:System.Threading.Tasks.Task.WhenAll%2A?displayProperty=nameWithType> vrátila.</span><span class="sxs-lookup"><span data-stu-id="20f04-258">The `Try` block has the `Await` expression for the task that <xref:System.Threading.Tasks.Task.WhenAll%2A?displayProperty=nameWithType> returned.</span></span> <span data-ttu-id="20f04-259">Když tři úkolů, ke kterému je úkol dokončený <xref:System.Threading.Tasks.Task.WhenAll%2A?displayProperty=nameWithType> se použije se dokončí.</span><span class="sxs-lookup"><span data-stu-id="20f04-259">The task is complete when the three tasks to which <xref:System.Threading.Tasks.Task.WhenAll%2A?displayProperty=nameWithType> is applied are complete.</span></span>

<span data-ttu-id="20f04-260">Všechny tři úkoly dojde k výjimce.</span><span class="sxs-lookup"><span data-stu-id="20f04-260">Each of the three tasks causes an exception.</span></span> <span data-ttu-id="20f04-261">`Catch` Bloku prochází výjimky, které jsou součástí `Exception.InnerExceptions` vlastnosti úkolu, který `Task.WhenAll` vrátila.</span><span class="sxs-lookup"><span data-stu-id="20f04-261">The `Catch` block iterates through the exceptions, which are found in the `Exception.InnerExceptions` property of the task that `Task.WhenAll` returned.</span></span>

[!code-vb[csAsyncExceptions#3](~/samples/snippets/visualbasic/VS_Snippets_VBCSharp/csasyncexceptions/vb/class1.vb#3)]

## <a name="see-also"></a><span data-ttu-id="20f04-262">Viz také:</span><span class="sxs-lookup"><span data-stu-id="20f04-262">See also</span></span>

- <xref:Microsoft.VisualBasic.Information.Err%2A>
- <xref:System.Exception>
- [<span data-ttu-id="20f04-263">Příkaz Exit</span><span class="sxs-lookup"><span data-stu-id="20f04-263">Exit Statement</span></span>](exit-statement.md)
- [<span data-ttu-id="20f04-264">Příkaz On Error</span><span class="sxs-lookup"><span data-stu-id="20f04-264">On Error Statement</span></span>](on-error-statement.md)
- [<span data-ttu-id="20f04-265">Doporučené postupy pro používání fragmentů kódu</span><span class="sxs-lookup"><span data-stu-id="20f04-265">Best Practices for Using Code Snippets</span></span>](/visualstudio/ide/best-practices-for-using-code-snippets)
- [<span data-ttu-id="20f04-266">Zpracování výjimek</span><span class="sxs-lookup"><span data-stu-id="20f04-266">Exception Handling</span></span>](../../../standard/parallel-programming/exception-handling-task-parallel-library.md)
- [<span data-ttu-id="20f04-267">Příkaz Throw</span><span class="sxs-lookup"><span data-stu-id="20f04-267">Throw Statement</span></span>](throw-statement.md)